<?xml version="1.0" encoding="utf-8"?>
<!-- =================================================================================== -->
<!-- |    This document was autogenerated by xacro from copernicus.xacro               | -->
<!-- |    EDITING THIS FILE BY HAND IS NOT RECOMMENDED                                 | -->
<!-- =================================================================================== -->
<!--

Copyright (c) 2021, Botsync Pte. Ltd.
All rights reserved.

Redistribution and use in source and binary forms, with or without
modification, are permitted provided that the following conditions are met:
    * Redistributions of source code must retain the above copyright
      notice, this list of conditions and the following disclaimer.
    * Redistributions in binary form must reproduce the above copyright
      notice, this list of conditions and the following disclaimer in the
      documentation and/or other materials provided with the distribution.
    * Neither the name of the Botsync Pte. Ltd. nor the 
      names of its contributors may be used to endorse or promote products
      derived from this software without specific prior written permission.

THIS SOFTWARE IS PROVIDED BY THE COPYRIGHT HOLDERS AND CONTRIBUTORS "AS IS" AND
ANY EXPRESS OR IMPLIED WARRANTIES, INCLUDING, BUT NOT LIMITED TO, THE IMPLIED
WARRANTIES OF MERCHANTABILITY AND FITNESS FOR A PARTICULAR PURPOSE ARE
DISCLAIMED. IN NO EVENT SHALL <COPYRIGHT HOLDER> BE LIABLE FOR ANY
DIRECT, INDIRECT, INCIDENTAL, SPECIAL, EXEMPLARY, OR CONSEQUENTIAL DAMAGES
(INCLUDING, BUT NOT LIMITED TO, PROCUREMENT OF SUBSTITUTE GOODS OR SERVICES;
LOSS OF USE, DATA, OR PROFITS; OR BUSINESS INTERRUPTION) HOWEVER CAUSED AND
ON ANY THEORY OF LIABILITY, WHETHER IN CONTRACT, STRICT LIABILITY, OR TORT
(INCLUDING NEGLIGENCE OR OTHERWISE) ARISING IN ANY WAY OUT OF THE USE OF THIS
SOFTWARE, EVEN IF ADVISED OF THE POSSIBILITY OF SUCH DAMAGE.

-->
<robot name="copernicus">
<mujoco>
        <compiler meshdir="meshes"                  balanceinertia="true"                  strippath="false"/>
        <option collision="predefined" cone="elliptic" jacobian="sparse" tolerance="1e-6" iterations="30" solver="CG" timestep="0.002"/>
</mujoco>
  <material name="blue">
    <color rgba="0 0 0.8 1"/>
  </material>
  <material name="white">
    <color rgba="1 1 1 1"/>
  </material>
  <material name="gray">
    <color rgba="0.5 0.5 0.5 1"/>
  </material>
  <!--<xacro:arg name="camera_enabled" default="false"/>
    <xacro:arg name="intel_d435i_enabled" default="false"/>-->
  <!-- Footprint -->
  <link name="footprint"/>
  <!-- Joint from footprint to base link(chassis) -->
  <joint name="base_footprint_joint" type="fixed">
    <origin rpy="0 0 0" xyz="0 0 0"/>
    <parent link="base_link"/>
    <child link="footprint"/>
  </joint>
  <!-- Chassis a.k.a base_link -->
  <link name="base_link">
    <visual>
      <origin rpy="0 0 0" xyz="0 0 0"/>
      <geometry>
        <mesh filename="copernicus.stl" scale="0.1 0.1 0.1"/>
      </geometry>
      <material name="gray"/>
    </visual>
    <collision>
      <origin rpy="0 0 0" xyz="0 0 0"/>
      <geometry>
        <mesh filename="copernicus.stl" scale="0.1 0.1 0.1"/>
      </geometry>
    </collision>
    <inertial>
      <mass value="5.674"/>
      <inertia ixx="3.28" ixy="0.0" ixz="0.0" iyy="3.69" iyz="0.0" izz="2.26"/>
    </inertial>
  </link>
  <!-- Wheel Link -->
  <link name="front_right_wheel">
    <visual>
      <origin rpy="0 0 0" xyz="0 0 0"/>
      <geometry>
        <mesh filename="wheel.stl" scale="0.1 0.1 0.1"/>
      </geometry>
      <material name="black"/>
    </visual>
    <collision>
      <origin rpy="0 0 0" xyz="0 0 0"/>
      <geometry>
        <mesh filename="wheel.stl" scale="0.1 0.1 0.1"/><!--<cylinder length="0.12" radius="0.18"/>-->
      </geometry>
    </collision>
    <inertial>
      <mass value="2.637"/>
      <origin xyz="0 0 0"/>
      <inertia ixx="0.739" ixy="0.17" ixz="0.236" iyy="0.741" iyz="0.299" izz="0.46"/>
    </inertial>
  </link>
  <!-- Wheel Joint -->
  <joint name="front_right_wheel_joint" type="continuous">
    <parent link="base_link"/>
    <child link="front_right_wheel"/>
    <origin rpy="0 0 0" xyz="0.2203 -0.2949 0.073"/>
    <axis xyz="0 1 0"/>
  </joint>
  <!-- Wheel Transmission -->
  <transmission name="front_right_wheel_transmission" type="SimpleTransmission">
    <type>transmission_interface/SimpleTransmission</type>
    <joint name="front_right_wheel_joint">
      <hardwareInterface>hardware_interface/VelocityJointInterface</hardwareInterface>
    </joint>
    <actuator name="front_right_motor">
      <mechanicalReduction>1</mechanicalReduction>
    </actuator>
  </transmission>
  <!-- Wheel Link -->
  <link name="back_right_wheel">
    <visual>
      <origin rpy="0 0 0" xyz="0 0 0"/>
      <geometry>
        <mesh filename="wheel.stl" scale="0.1 0.1 0.1"/>
      </geometry>
      <material name="black"/>
    </visual>
    <collision>
      <origin rpy="0 0 0" xyz="0 0 0"/>
      <geometry>
        <mesh filename="wheel.stl" scale="0.1 0.1 0.1"/><!--<cylinder length="0.12" radius="0.18"/>-->
      </geometry>
    </collision>
    <inertial>
      <mass value="2.637"/>
      <origin xyz="0 0 0"/>
      <inertia ixx="0.739" ixy="0.17" ixz="0.236" iyy="0.741" iyz="0.299" izz="0.46"/>
    </inertial>
  </link>
  <!-- Wheel Joint -->
  <joint name="back_right_wheel_joint" type="continuous">
    <parent link="base_link"/>
    <child link="back_right_wheel"/>
    <origin rpy="0 0 0" xyz="-0.2203 -0.2949 0.073"/>
    <axis xyz="0 1 0"/>
  </joint>
  <!-- Wheel Transmission -->
  <transmission name="back_right_wheel_transmission" type="SimpleTransmission">
    <type>transmission_interface/SimpleTransmission</type>
    <joint name="back_right_wheel_joint">
      <hardwareInterface>hardware_interface/VelocityJointInterface</hardwareInterface>
    </joint>
    <actuator name="back_right_motor">
      <mechanicalReduction>1</mechanicalReduction>
    </actuator>
  </transmission>
  <!-- Wheel Link -->
  <link name="front_left_wheel">
    <visual>
      <origin rpy="0 0 0" xyz="0 0 0"/>
      <geometry>
        <mesh filename="wheel.stl" scale="0.1 0.1 0.1"/>
      </geometry>
      <material name="black"/>
    </visual>
    <collision>
      <origin rpy="0 0 0" xyz="0 0 0"/>
      <geometry>
        <mesh filename="wheel.stl" scale="0.1 0.1 0.1"/><!--<cylinder length="0.12" radius="0.18"/>-->
      </geometry>
    </collision>
    <inertial>
      <mass value="2.637"/>
      <origin xyz="0 0 0"/>
      <inertia ixx="0.739" ixy="0.17" ixz="0.236" iyy="0.741" iyz="0.299" izz="0.46"/>
    </inertial>
  </link>
  <!-- Wheel Joint -->
  <joint name="front_left_wheel_joint" type="continuous">
    <parent link="base_link"/>
    <child link="front_left_wheel"/>
    <origin rpy="0 0 0" xyz="0.2203 0.2949 0.073"/>
    <axis xyz="0 1 0"/>
  </joint>
  <!-- Wheel Transmission -->
  <transmission name="front_left_wheel_transmission" type="SimpleTransmission">
    <type>transmission_interface/SimpleTransmission</type>
    <joint name="front_left_wheel_joint">
      <hardwareInterface>hardware_interface/VelocityJointInterface</hardwareInterface>
    </joint>
    <actuator name="front_left_motor">
      <mechanicalReduction>1</mechanicalReduction>
    </actuator>
  </transmission>
  <!-- Wheel Link -->
  <link name="back_left_wheel">
    <visual>
      <origin rpy="0 0 0" xyz="0 0 0"/>
      <geometry>
        <mesh filename="wheel.stl" scale="0.1 0.1 0.1"/>
      </geometry>
      <material name="black"/>
    </visual>
    <collision>
      <origin rpy="0 0 0" xyz="0 0 0"/>
      <geometry>
        <mesh filename="wheel.stl" scale="0.1 0.1 0.1"/><!--<cylinder length="0.12" radius="0.18"/>-->
      </geometry>
    </collision>
    <inertial>
      <mass value="2.637"/>
      <origin xyz="0 0 0"/>
      <inertia ixx="0.739" ixy="0.17" ixz="0.236" iyy="0.741" iyz="0.299" izz="0.46"/>
    </inertial>
  </link>
  <!-- Wheel Joint -->
  <joint name="back_left_wheel_joint" type="continuous">
    <parent link="base_link"/>
    <child link="back_left_wheel"/>
    <origin rpy="0 0 0" xyz="-0.2203 0.2949 0.073"/>
    <axis xyz="0 1 0"/>
  </joint>
  <!-- Wheel Transmission -->
  <transmission name="back_left_wheel_transmission" type="SimpleTransmission">
    <type>transmission_interface/SimpleTransmission</type>
    <joint name="back_left_wheel_joint">
      <hardwareInterface>hardware_interface/VelocityJointInterface</hardwareInterface>
    </joint>
    <actuator name="back_left_motor">
      <mechanicalReduction>1</mechanicalReduction>
    </actuator>
  </transmission>
  <joint name="imu_joint" type="fixed">
    <parent link="base_link"/>
    <child link="imu"/>
    <origin rpy="0 0 0" xyz="0 0 0.11457"/>
  </joint>
  <link name="imu">
    <inertial>
      <mass value="0.001"/>
      <origin rpy="0 0 0" xyz="0 0 0"/>
      <inertia ixx="1e-09" ixy="0.0" ixz="0.0" iyy="1e-09" iyz="0.0" izz="1e-09"/>
    </inertial>
  </link>
  <!-- lidar link -->
  <link name="lidar">
    <visual>
      <origin rpy="0 0 0.785398" xyz="-0.018 0 -0.03"/>
      <geometry>
        <mesh filename="rplidar.stl"/>
      </geometry>
    </visual>
    <collision>
      <origin rpy="0 0 0" xyz="-0.018 0 -0.03"/>
      <geometry>
        <mesh filename="rplidar.stl"/>
      </geometry>
    </collision>
    <inertial>
      <origin rpy="0 0 0" xyz="-0.018 0 -0.005"/>
      <mass value="0.3"/>
      <inertia ixx="0.00028" ixy="0.0" ixz="0.0" iyy="0.00028" iyz="0.0" izz="0.00022"/>
    </inertial>
  </link>
  <!-- lidar joint -->
  <joint name="lidar_joint" type="fixed">
    <origin rpy="0 0 0" xyz="0.127 0.0 0.395"/>
    <parent link="base_link"/>
    <child link="lidar"/>
  </joint>
  <!-- CAMERA -->
  <!--<xacro:if value="$(arg camera_enabled)">
            <xacro:include filename="$(find copernicus_description)/urdf/accessories/camera_copernicus.urdf.xacro"/>
            <xacro:camera_ intel_d435i_enabled="$(arg intel_d435i_enabled)" robot_namespace="$(arg robot_namespace)"></xacro:camera_>
        </xacro:if>-->
  <!--ROBOT GAZEBO TAG-->
</robot>

